<?xml version="1.0" encoding="UTF-8"?>
<testsuite name="UnitTest_tests.MLTest-20211201181813" tests="1" file="UnitTest_tests.py" time="28.580" timestamp="2021-12-01T18:18:51" failures="0" errors="1" skipped="0">
	<testcase classname="UnitTest_tests.MLTest" name="test_age" time="28.580" timestamp="2021-12-01T18:18:51">
		<error type="NotFoundError" message="Unsuccessful TensorSliceReader constructor: Failed to find any matching files for ./models/checkpoint"><![CDATA[Traceback (most recent call last):
  File "C:\Users\Nova\AppData\Local\Programs\Python\Python38\lib\unittest\case.py", line 60, in testPartExecutor
    yield
  File "C:\Users\Nova\AppData\Local\Programs\Python\Python38\lib\unittest\case.py", line 672, in run
    self._callSetUp()
  File "C:\Users\Nova\AppData\Local\Programs\Python\Python38\lib\unittest\case.py", line 630, in _callSetUp
    self.setUp()
  File "e:\niit\semester 7\capstone project ii\project\venv\agender\ui\agender_ui\pybuilder\src\unittest\python\UnitTest_tests.py", line 45, in setUp
    self.model, self.prediction_age = age_model()
  File "../login_signup\detectors.py", line 25, in age_model
    model.load_weights('./models/checkpoint')
  File "e:\niit\semester 7\capstone project ii\project\venv\lib\site-packages\keras\utils\traceback_utils.py", line 67, in error_handler
    raise e.with_traceback(filtered_tb) from None
  File "e:\niit\semester 7\capstone project ii\project\venv\lib\site-packages\tensorflow\python\training\py_checkpoint_reader.py", line 35, in error_translator
    raise errors_impl.NotFoundError(None, None, error_message)
tensorflow.python.framework.errors_impl.NotFoundError: Unsuccessful TensorSliceReader constructor: Failed to find any matching files for ./models/checkpoint
]]></error>
	</testcase>
</testsuite>
